<html>
<head><meta charset="utf-8"><title>pop-tools error after package updates · python-questions · Zulip Chat Archive</title></head>
<h2>Stream: <a href="http://127.0.0.1:4000/html/stream/10-python-questions/index.html">python-questions</a></h2>
<h3>Topic: <a href="http://127.0.0.1:4000/html/stream/10-python-questions/topic/pop-tools.20error.20after.20package.20updates.html">pop-tools error after package updates</a></h3>

<hr>


<head><link href="http://127.0.0.1:4000/style.css" rel="stylesheet"></head>

<a name="94585"></a>
<h4><a href="https://zulip2.cloud.ucar.edu#narrow/stream/10-python-questions/topic/pop-tools%20error%20after%20package%20updates/near/94585" class="zl"><img src="../../../assets/img/zulip.svg" alt="view this post on Zulip" style="width:20px;height:20px;"></a> Mira Berdahl <a href="http://127.0.0.1:4000/html/stream/10-python-questions/topic/pop-tools.20error.20after.20package.20updates.html#94585">(Jan 18 2024 at 19:39)</a>:</h4>
<p>It looks like after updating some of my packages, pop-tools breaks. It worked well before this update, and appears to be related a deprecated np.float() call.  Any plans to update the pop-tools package? Or other workaround recommendations?</p>
<p>When trying to get the grid:</p>
<div class="codehilite"><pre><span></span><code>grid_name = &#39;POP_tx0.1v3&#39;  # our 0.1 degree pop grid.
grid = pop_tools.get_grid(grid_name)
</code></pre></div>
<p>The following error is thrown: </p>
<div class="codehilite"><pre><span></span><code>---------------------------------------------------------------------------
AttributeError                            Traceback (most recent call last)
Input In [4], in &lt;module&gt;
      1 # using pop tools, get the region mask.
      2 grid_name = &#39;POP_tx0.1v3&#39;  # our 0.1 degree pop grid.
----&gt; 3 grid = pop_tools.get_grid(grid_name)

File /glade/work/mberdahl/miniconda/envs/pangeo/lib/python3.9/site-packages/pop_tools/grid.py:142, in get_grid(grid_name, scrip)
    139 grid_file_data = np.fromfile(horiz_grid_fname, dtype=&#39;&gt;f8&#39;, count=-1)
    140 grid_file_data = grid_file_data.reshape((7, nlat, nlon))
--&gt; 142 ULAT = grid_file_data[0, :, :].astype(np.float)
    143 ULONG = grid_file_data[1, :, :].astype(np.float)
    144 HTN = grid_file_data[2, :, :].astype(np.float)

File /glade/work/mberdahl/miniconda/envs/pangeo/lib/python3.9/site-packages/numpy/__init__.py:324, in __getattr__(attr)
    319     warnings.warn(
    320         f&quot;In the future `np.{attr}` will be defined as the &quot;
    321         &quot;corresponding NumPy scalar.&quot;, FutureWarning, stacklevel=2)
    323 if attr in __former_attrs__:
--&gt; 324     raise AttributeError(__former_attrs__[attr])
    326 if attr == &#39;testing&#39;:
    327     import numpy.testing as testing

AttributeError: module &#39;numpy&#39; has no attribute &#39;float&#39;.
`np.float` was a deprecated alias for the builtin `float`. To avoid this error in existing code, use `float` by itself. Doing this will not modify any behavior and is safe. If you specifically wanted the numpy scalar type, use `np.float64` here.
The aliases was originally deprecated in NumPy 1.20; for more details and guidance see the original release note at:
    https://numpy.org/devdocs/release/1.20.0-notes.html#deprecations
</code></pre></div>



<a name="94631"></a>
<h4><a href="https://zulip2.cloud.ucar.edu#narrow/stream/10-python-questions/topic/pop-tools%20error%20after%20package%20updates/near/94631" class="zl"><img src="../../../assets/img/zulip.svg" alt="view this post on Zulip" style="width:20px;height:20px;"></a> Katelyn FitzGerald <a href="http://127.0.0.1:4000/html/stream/10-python-questions/topic/pop-tools.20error.20after.20package.20updates.html#94631">(Jan 18 2024 at 22:28)</a>:</h4>
<p>It looks like this might have been updated in the last release 2023.06.0 (<a href="https://github.com/NCAR/pop-tools">https://github.com/NCAR/pop-tools</a>).  Do you know what version of pop-tools you're using?  </p>
<p>I'm not sure on the maintainer question - curious myself.</p>



<a name="94637"></a>
<h4><a href="https://zulip2.cloud.ucar.edu#narrow/stream/10-python-questions/topic/pop-tools%20error%20after%20package%20updates/near/94637" class="zl"><img src="../../../assets/img/zulip.svg" alt="view this post on Zulip" style="width:20px;height:20px;"></a> Mira Berdahl <a href="http://127.0.0.1:4000/html/stream/10-python-questions/topic/pop-tools.20error.20after.20package.20updates.html#94637">(Jan 18 2024 at 23:11)</a>:</h4>
<p>Well, I had pop-tools version 2021.5.28. <br>
I just upgraded it, but now I am encountering the following error when importing cartopy</p>
<div class="codehilite"><pre><span></span><code>---------------------------------------------------------------------------
ImportError                               Traceback (most recent call last)
Input In [1], in &lt;module&gt;
      2 import xarray as xr
      3 #from matplotlib import pyplot as plt
----&gt; 4 import cartopy.crs as ccrs
      5 import nc_time_axis as nc_time_axis
      6 import cmocean

File /glade/work/mberdahl/miniconda/envs/pangeo/lib/python3.9/site-packages/cartopy/__init__.py:107, in &lt;module&gt;
    102     pass
    105 # Commonly used sub-modules. Imported here to provide end-user
    106 # convenience.
--&gt; 107 import cartopy.crs
    108 import cartopy.feature

File /glade/work/mberdahl/miniconda/envs/pangeo/lib/python3.9/site-packages/cartopy/crs.py:23, in &lt;module&gt;
     21 import numpy as np
     22 import shapely.geometry as sgeom
---&gt; 23 from pyproj import Transformer
     24 from pyproj.exceptions import ProjError
     25 from shapely.prepared import prep

File /glade/work/mberdahl/miniconda/envs/pangeo/lib/python3.9/site-packages/pyproj/__init__.py:49, in &lt;module&gt;
     32 __all__ = [
     33     &quot;Proj&quot;,
     34     &quot;Geod&quot;,
   (...)
     45     &quot;show_versions&quot;,
     46 ]
     47 import warnings
---&gt; 49 import pyproj.network
     50 from pyproj._datadir import (  # noqa: F401 pylint: disable=unused-import
     51     _pyproj_global_context_initialize,
     52     set_use_global_context,
     53 )
     54 from pyproj._show_versions import (  # noqa: F401 pylint: disable=unused-import
     55     show_versions,
     56 )

File /glade/work/mberdahl/miniconda/envs/pangeo/lib/python3.9/site-packages/pyproj/network.py:10, in &lt;module&gt;
      6 from typing import Union
      8 import certifi
---&gt; 10 from pyproj._network import (  # noqa: F401 pylint: disable=unused-import
     11     _set_ca_bundle_path,
     12     is_network_enabled,
     13     set_network_enabled,
     14 )
     17 def set_ca_bundle_path(ca_bundle_path: Union[Path, str, bool, None] = None) -&gt; None:
     18     &quot;&quot;&quot;
     19     .. versionadded:: 3.0.0
     20
   (...)
     38         variables.
     39     &quot;&quot;&quot;

ImportError: libcrypto.so.3: cannot open shared object file: No such file or directory
</code></pre></div>



<a name="94658"></a>
<h4><a href="https://zulip2.cloud.ucar.edu#narrow/stream/10-python-questions/topic/pop-tools%20error%20after%20package%20updates/near/94658" class="zl"><img src="../../../assets/img/zulip.svg" alt="view this post on Zulip" style="width:20px;height:20px;"></a> Katelyn FitzGerald <a href="http://127.0.0.1:4000/html/stream/10-python-questions/topic/pop-tools.20error.20after.20package.20updates.html#94658">(Jan 18 2024 at 23:52)</a>:</h4>
<p>It looks like the system you're working on doesn't have the right version of openssl/libcrypto.so.3.  Is this on casper?  Might be worth looping in the HPC folks if so.</p>



<a name="94687"></a>
<h4><a href="https://zulip2.cloud.ucar.edu#narrow/stream/10-python-questions/topic/pop-tools%20error%20after%20package%20updates/near/94687" class="zl"><img src="../../../assets/img/zulip.svg" alt="view this post on Zulip" style="width:20px;height:20px;"></a> Mira Berdahl <a href="http://127.0.0.1:4000/html/stream/10-python-questions/topic/pop-tools.20error.20after.20package.20updates.html#94687">(Jan 19 2024 at 17:17)</a>:</h4>
<p>Thanks <span class="user-mention" data-user-id="339">@Katelyn FitzGerald</span> , will do.<br>
This is on casper, yes.</p>



<hr><p>Last updated: May 16 2025 at 17:14 UTC</p>
</html>